Workbook
Name Slicer_Category: #N/A
Name Slicer_Region: #N/A

Sheet Raw_Sales_Data
A1: Order_ID | B1: Order_Date | C1: Region | D1: State | E1: Salesperson | F1: Category | G1: Product | H1: Quantity | I1: Unit_Price | J1: Discount | K1: Revenue | L1: Cost | M1: Profit | N1: Customer_Type | O1: Payment_Mode
A2: ORD10001 | B2: 45745 | C2: South | D2: Telangana | E2: Arjun | F2: Office Supplies | G2: Stationery Kit | H2: 5 | I2: 661.47 | J2: 0.03 | K2: 3208.15 | L2: 2033.77 | M2: 1174.38 | N2: Retail | O2: Debit Card
A3: ORD10002 | B3: 45910 | C3: NORTH | D3: Punjab | E3: Kavya | F3: Furniture | G3: Dining Table | H3: 8 | I3: 30205.11 | J3: 0.08 | K3: 222309.59 | L3: 170466.27 | M3: 51843.32 | N3: Corporate | O3: UPI
A4: ORD10003 | B4: 46021 | C4: South | D4: Tamil Nadu | E4: Priya | F4: Electronics | G4: Monitor | H4: 8 | I4: 17230.38 | J4: 0 | K4: 137843.05 | L4: 105920.34 | M4: 31922.71 | N4: Corporate | O4: UPI
A5: ORD10004 | B5: 46003 | C5: North | D5: Haryana | E5: Arjun | F5: Electronics | G5: Smartphone | H5: 4 | I5: 32122.57 | J5: 0.05 | K5: 122065.76 | L5: 86971.85 | M5: 35093.91 | N5: Retail | O5: Net Banking
A6: ORD10005 | B6: 45711 | C6: North | D6: Uttar Pradesh | E6: Arjun | F6: Home Appliances | G6: Microwave | H6: 6 | I6: 11790.84 | J6: 0.03 | K6: 68622.67 | L6: 54986.44 | M6: 13636.23 | N6: Corporate | O6: Cash
A7: ORD10006 | B7: 45909 | C7: WEST | D7: Gujarat | E7: Sneha | F7: Furniture | G7: Bed | H7: 6 | I7: 31090.91 | K7: 180949.07 | L7: 136961.54 | M7: 43987.53 | N7: Retail | O7: Cash
A8: ORD10007 | B8: 45672 | C8: South | D8: Karnataka | E8: Arjun | F8: Furniture | G8: Dining Table | H8: 1 | I8: 27018.59 | J8: 0.05 | K8: 25667.66 | L8: 16782.08 | M8: 8885.58 | N8: Retail | O8: UPI
A9: ORD10008 | B9: 45918 | C9: West | D9: Goa | E9: Amit | F9: Electronics | G9: Tablet | H9: 3 | I9: 22728.14 | J9: 0.08 | K9: 62729.66 | L9: 50503.96 | M9: 12225.7 | N9: Online | O9: Credit Card
A10: ORD10009 | B10: 45756 | C10: North | D10: Haryana | E10: Amit | F10: Office Supplies | G10: Office Chair | H10: 1 | I10: 8371.52 | J10: 0.03 | K10: 8120.38 | L10: 5668.38 | M10: 2452 | N10: Corporate | O10: Debit Card
A11: ORD10010 | B11: 45940 | C11: East | D11: Bihar | E11: Vikram | F11: Furniture | G11: Bookshelf | H11: 1 | I11: 11390.24 | J11: 0.03 | K11: 11048.54 | L11: 7529.1 | M11: 3519.44 | N11: Corporate | O11: Credit Card
A12: ORD10011 | B12: 45888 | C12: North | D12: Delhi | E12: Rahul | F12: Electronics | G12: Laptop | H12: 4 | I12: 65658.07 | J12: 0.08 | K12: 241621.68 | L12: 157885.16 | M12: 83736.52 | N12: Retail | O12: Debit Card
A13: ORD10012 | B13: 45791 | C13: North | D13: Delhi | E13: Kavya | F13: Home Appliances | G13: Microwave | H13: 6 | I13: 12730.5 | J13: 0.08 | K13: 70272.35 | L13: 48554.83 | M13: 21717.52 | N13: Corporate | O13: Net Banking
A14: ORD10013 | B14: 45940 | C14: North | D14: Punjab | E14: Neha | F14: Home Appliances | G14: Washing Machine | H14: 7 | I14: 38281.49 | J14: 0.03 | K14: 259931.29 | L14: 168022.83 | M14: 91908.46 | N14: Corporate | O14: Net Banking
A15: ORD10014 | B15: 45809 | C15: South | D15: Tamil Nadu | E15: Arjun | F15: Electronics | G15: Tablet | H15: 1 | I15: 21946.6 | J15: 0.08 | K15: 20190.87 | L15: 13823.86 | M15: 6367.01 | N15: Online | O15: UPI
A16: ORD10015 | B16: 45738 | C16: South | D16: Karnataka | E16: Amit | F16: Electronics | G16: Monitor | H16: 6 | I16: 18565.36 | J16: 0.08 | K16: 102480.77 | L16: 67180.33 | M16: 35300.44 | N16: Retail | O16: Credit Card
A17: ORD10016 | B17: 45817 | C17: South | D17: Karnataka | E17: Arjun | F17: Electronics | G17: Laptop | H17: 1 | I17: 62291.44 | J17: 0 | K17: 62291.44 | L17: 45937.98 | M17: 16353.46 | N17: Corporate | O17: Net Banking
A18: ORD10017 | B18: 45801 | C18: North | D18: Uttar Pradesh | E18: Rahul | F18: Electronics | G18: Headphones | H18: 4 | I18: 4848.06 | J18: 0.05 | K18: 18422.65 | L18: 15031.84 | M18: 3390.81 | N18: Online | O18: Net Banking
A19: ORD10018 | B19: 45805 | C19: South | D19: Andhra Pradesh | E19: Vikram | F19: Furniture | G19: Bed | H19: 3 | I19: 28657.16 | J19: 0.08 | K19: 79093.75 | L19: 64404.48 | M19: 14689.27 | N19: Corporate | O19: Net Banking
... A39: ORD10038 | B39: 45669 | C39: South | D39: Tamil Nadu | E39: Rahul | F39: Furniture | G39: Bookshelf | H39: 1 | I39: 11811.7 | J39: 0.1 | K39: 10630.53 | L39: 7090.46 | M39: 3540.07 | N39: Retail | O39: Credit Card
A40: ORD10039 | C40: North | D40: Punjab | E40: Rahul | F40: Electronics | G40: Smartphone | H40: 8 | I40: 29449.9 | J40: 0.08 | K40: 216751.29 | L40: 152105.2 | M40: 64646.09 | N40: Retail | O40: Net Banking
A41: ORD10040 | B41: 45849 | C41: East | D41: Odisha | E41: Vikram | F41: Furniture | G41: Bed | H41: 1 | I41: 31456.71 | J41: 0.03 | K41: 30513.01 | L41: 20217.48 | M41: 10295.53 | N41: Corporate | O41: Debit Card
A42: ORD10041 | B42: 46018 | C42: South | D42: Karnataka | E42: Amit | F42: Office Supplies | G42: Stationery Kit | H42: 4 | I42: 692.05 | J42: 0.08 | K42: 2546.73 | L42: 2040.16 | M42: 506.57 | N42: Retail | O42: UPI
A43: ORD10042 | B43: 45733 | C43: South | D43: Andhra Pradesh | E43: Amit | F43: Electronics | G43: Tablet | H43: 3 | I43: 21609.99 | J43: 0 | K43: 64829.97 | L43: 54281.59 | M43: 10548.38 | N43: Retail | O43: Net Banking
A44: ORD10043 | B44: 45710 | C44: West | D44: Goa | E44: Sneha | F44: Home Appliances | G44: Mixer Grinder | H44: 5 | I44: 4834.57 | J44: 0.03 | K44: 23447.66 | L44: 18322.11 | M44: 5125.55 | N44: Online | O44: UPI
A45: ORD10044 | B45: 45896 | C45: North | D45: Delhi | E45: Priya | F45: Furniture | G45: Dining Table | H45: 5 | I45: 29061.92 | J45: 0.05 | K45: 138044.12 | L45: 108971.97 | M45: 29072.15 | N45: Retail | O45: Credit Card
A46: ORD10045 | B46: 45662 | C46: West | D46: Maharashtra | E46: Vikram | F46: Furniture | G46: Coffee Table | H46: 8 | I46: 7918.96 | J46: 0.1 | K46: 57016.5 | L46: 45014.42 | M46: 12002.08 | N46: Corporate | O46: Debit Card
A47: ORD10046 | B47: 45909 | C47: East | D47: West Bengal | E47: Amit | F47: Furniture | G47: Sofa | H47: 7 | I47: 34087.39 | J47: 0.08 | K47: 219522.8 | L47: 154555.55 | M47: 64967.25 | N47: Retail | O47: Cash
A48: ORD10047 | B48: 45783 | C48: South | D48: Tamil Nadu | E48: Rahul | F48: Electronics | G48: Tablet | H48: 7 | I48: 21769.27 | J48: 0.03 | K48: 147813.35 | L48: 106018.9 | M48: 41794.45 | N48: Retail | O48: Net Banking
A49: ORD10048 | B49: 45969 | C49: East | D49: Bihar | E49: Amit | F49: Office Supplies | G49: Desk | H49: 5 | I49: 13412.01 | J49: 0.05 | K49: 63707.07 | L49: 46802.5 | M49: 16904.57 | N49: Corporate | O49: Cash
A50: ORD10049 | B50: 45886 | C50: West | D50: Goa | E50: Vikram | F50: Furniture | G50: Coffee Table | H50: 7 | I50: 9031.95 | J50: 0.05 | K50: 60062.5 | L50: 51552.34 | M50: 8510.16 | N50: Retail | O50: Debit Card
A51: ORD10050 | B51: 45669 | C51: West | D51: Gujarat | E51: Arjun | F51: Office Supplies | G51: Printer | H51: 5 | I51: 15472.62 | J51: 0.05 | K51: 73494.95 | L51: 58568.43 | M51: 14926.52 | N51: Online | O51: Net Banking
A52: ORD10051 | B52: 46014 | C52: North | D52: Delhi | E52: Kavya | F52: Electronics | G52: Monitor | H52: 2 | I52: 17678.21 | J52: 0.03 | K52: 34295.73 | L52: 23452.28 | M52: 10843.45 | N52: Online | O52: Debit Card
A53: ORD10052 | B53: 45910 | C53: East | D53: West Bengal | E53: Amit | F53: Electronics | G53: Monitor | H53: 5 | I53: 18532.03 | J53: 0.03 | K53: 89880.33 | L53: 75375.67 | M53: 14504.66 | N53: Online | O53: Debit Card
A54: ORD10053 | B54: 45722 | C54: East | D54: Bihar | E54: Amit | F54: Home Appliances | G54: Washing Machine | H54: 3 | I54: 33380.46 | J54: 0 | K54: 100141.38 | L54: 71135.55 | M54: 29005.83 | N54: Corporate | O54: UPI
A55: ORD10054 | B55: 45968 | C55: South | D55: Karnataka | E55: Arjun | F55: Home Appliances | G55: Microwave | H55: 3 | I55: 12132.64 | J55: 0 | K55: 36397.91 | L55: 22888.36 | M55: 13509.55 | N55: Online | O55: UPI
A56: ORD10055 | C56: South | D56: Telangana | E56: Neha | F56: Furniture | G56: Coffee Table | H56: 5 | I56: 9104.88 | J56: 0.1 | K56: 40971.97 | L56: 27834.86 | M56: 13137.11 | N56: Retail | O56: UPI
A57: ORD10056 | B57: 45811 | C57: West | D57: Maharashtra | E57: Sneha | F57: Electronics | G57: Laptop | H57: 8 | I57: 66228.53 | J57: 0.05 | K57: 503336.86 | L57: 325786.71 | M57: 177550.15 | N57: Corporate | O57: Debit Card
A58: ORD10057 | B58: 45960 | C58: South | D58: Andhra Pradesh | E58: Amit | F58: Home Appliances | G58: Mixer Grinder | H58: 6 | I58: 5301.32 | J58: 0.05 | K58: 30217.54 | L58: 19706.78 | M58: 10510.76 | N58: Corporate | O58: Cash
A59: ORD10058 | B59: 46004 | C59: East | D59: Odisha | E59: Rahul | F59: Electronics | G59: Monitor | H59: 2 | I59: 17569.69 | J59: 0.08 | K59: 32328.23 | L59: 23086.84 | M59: 9241.39 | N59: Retail | O59: Credit Card
...

Sheet Cleaned_Sales_Data
A1: Order_ID | B1: Order_Date | C1: Region | D1: State | E1: Salesperson | F1: Category | G1: Product | H1: Quantity | I1: Unit_Price | J1: Discount | K1: Revenue | L1: Cost | M1: Profit | N1: Customer_Type | O1: Payment_Mode
A2: ORD10785 | B2: 45748 | C2: East | D2: Bihar | E2: Vikram | F2: Office Supplies | G2: Notebook | H2: 1 | I2: 241.09 | J2: 0.15 | K2: 204.93 | L2: 163.98 | M2: 40.95 | N2: Corporate | O2: Net Banking
A3: ORD10711 | B3: 46000 | C3: South | D3: Andhra Pradesh | E3: Amit | F3: Office Supplies | G3: Notebook | H3: 1 | I3: 267.39 | J3: 0.1 | K3: 240.65 | L3: 197.86 | M3: 42.79 | N3: Online | O3: Cash
A4: ORD10089 | B4: 45923 | C4: South | D4: Karnataka | E4: Neha | F4: Office Supplies | G4: Notebook | H4: 1 | I4: 243.37 | J4: 0 | K4: 243.37 | L4: 194.89 | M4: 48.48 | N4: Retail | O4: Credit Card
A5: ORD10577 | B5: 45983 | C5: West | D5: Maharashtra | E5: Arjun | F5: Office Supplies | G5: Notebook | H5: 1 | I5: 234.23 | J5: 0.1 | K5: 210.8 | L5: 159.98 | M5: 50.82 | N5: Online | O5: Credit Card
A6: ORD10806 | B6: 45872 | C6: South | D6: Tamil Nadu | E6: Arjun | F6: Office Supplies | G6: Notebook | H6: 1 | I6: 269.68 | J6: 0 | K6: 269.68 | L6: 218.73 | M6: 50.95 | N6: Retail | O6: Debit Card
A7: ORD11005 | B7: 45842 | C7: South | D7: Karnataka | E7: Vikram | F7: Office Supplies | G7: Notebook | H7: 1 | I7: 262.61 | J7: 0 | K7: 262.61 | L7: 202.08 | M7: 60.53 | N7: Corporate | O7: UPI
A8: ORD10289 | B8: 45813 | C8: North | D8: Uttar Pradesh | E8: Priya | F8: Office Supplies | G8: Notebook | H8: 1 | I8: 263.42 | J8: 0.1 | K8: 237.07 | L8: 168.43 | M8: 68.64 | N8: Retail | O8: Debit Card
A9: ORD10371 | B9: 45985 | C9: West | D9: Goa | E9: Sneha | F9: Office Supplies | G9: Notebook | H9: 1 | I9: 252.17 | J9: 0.03 | K9: 244.61 | L9: 168.91 | M9: 75.7 | N9: Online | O9: Cash
A10: ORD10164 | B10: 45693 | C10: North | D10: Uttar Pradesh | E10: Sneha | F10: Office Supplies | G10: Notebook | H10: 2 | I10: 243.49 | J10: 0.1 | K10: 438.28 | L10: 353 | M10: 85.28 | N10: Retail | O10: UPI
A11: ORD10407 | B11: 45865 | C11: South | D11: Karnataka | E11: Rahul | F11: Office Supplies | G11: Stationery Kit | H11: 1 | I11: 669.32 | J11: 0.1 | K11: 602.39 | L11: 507.99 | M11: 94.4 | N11: Retail | O11: Cash
A12: ORD10139 | B12: 45900 | C12: East | D12: Jharkhand | E12: Priya | F12: Office Supplies | G12: Notebook | H12: 2 | I12: 253.91 | J12: 0.1 | K12: 457.04 | L12: 355.21 | M12: 101.83 | N12: Corporate | O12: Cash
A13: ORD10571 | B13: 45914 | C13: South | D13: Telangana | E13: Vikram | F13: Office Supplies | G13: Notebook | H13: 2 | I13: 242.63 | J13: 0 | K13: 485.25 | L13: 377.2 | M13: 108.05 | N13: Retail | O13: Debit Card
... A1181: ORD10056 | B1181: 45811 | C1181: West | D1181: Maharashtra | E1181: Sneha | F1181: Electronics | G1181: Laptop | H1181: 8 | I1181: 66228.53 | J1181: 0.05 | K1181: 503336.86 | L1181: 325786.71 | M1181: 177550.15 | N1181: Corporate | O1181: Debit Card

Sheet Monthly Trend
A3: Row Labels | B3: Total Revenue | C3: Total Profit
A4: Jan | B4: 9421909.4 | C4: 2403536
A5: Feb | B5: 8311136 | C5: 2127785.9
A6: Mar | B6: 9710176.6 | C6: 2473852.6
A7: Apr | B7: 9549827.9 | C7: 2401717.6
A8: May | B8: 9934935 | C8: 2598244.6
A9: Jun | B9: 9283745.9 | C9: 2412663.7
A10: Jul | B10: 8869023.6 | C10: 2187474.4
A11: Aug | B11: 8970946.1 | C11: 2253862.8
A12: Sep | B12: 8954553 | C12: 2381184.3
A13: Oct | B13: 9992152.9 | C13: 2686815.4
A14: Nov | B14: 12873167 | C14: 3335606.8
A15: Dec | B15: 8891700.4 | C15: 2277265.6
A16: Grand Total | B16: 1.1476327e+08 | C16: 29540010

Sheet Region Analysis
A3: Row Labels | B3: Total Revenue | C3: Total Profit
A4: East | B4: 22862092 | C4: 5940513.2
A5: North | B5: 31802415 | C5: 8068792
A6: South | B6: 32131258 | C6: 8199036.3
A7: Unknown | B7: 659386.42 | C7: 188943.9
A8: West | B8: 27308122 | C8: 7142724.2
A9: Grand Total | B9: 1.1476327e+08 | C9: 29540010

Sheet Category Analysis
A3: Row Labels | B3: Total Revenue | C3: Total Profit
A4: Electronics | B4: 49794962 | C4: 12880500
A5: Furniture | B5: 17817791 | C5: 4649348.2
A6: Home Appliances | B6: 39199478 | C6: 9928626.7
A7: Office Supplies | B7: 7951041.2 | C7: 2081534.9
A8: Grand Total | B8: 1.1476327e+08 | C8: 29540010

Sheet Product Analysis
A3: Row Labels | B3: Total Revenue | C3: Total Profit
A4: Laptop | B4: 21947898 | C4: 5735129.8
A5: Air Conditioner | B5: 15323679 | C5: 3706946.9
A6: Washing Machine | B6: 10078775 | C6: 2541211.8
A7: Refrigerator | B7: 9941796.8 | C7: 2662958.6
A8: Tablet | B8: 9818729 | C8: 2511674.6
A9: Smartphone | B9: 9761957.8 | C9: 2571841.2
A10: Monitor | B10: 6934566.5 | C10: 1725547.2
A11: Sofa | B11: 5682407.1 | C11: 1565870.9
A12: Bed | B12: 4412698.8 | C12: 1032446.3
A13: Dining Table | B13: 4199874.3 | C13: 1166260.8
A14: Printer | B14: 3261707.2 | C14: 840484.97
A15: Desk | B15: 2916989.1 | C15: 791062.77
... A24: Grand Total | B24: 1.1476327e+08 | C24: 29540010

Sheet Salesperson Analysis
A3: Row Labels | B3: Total Revenue | C3: Total Profit
A4: Arjun | B4: 15884616 | C4: 3933996.5
A5: Kavya | B5: 15229045 | C5: 3965627.8
A6: Sneha | B6: 15171648 | C6: 4024259.1
A7: Amit | B7: 14653316 | C7: 3668662.8
A8: Rahul | B8: 14531746 | C8: 3739093.5
A9: Vikram | B9: 13597235 | C9: 3402812.8
A10: Neha | B10: 12956291 | C10: 3520397.1
A11: Priya | B11: 11734342 | C11: 2986407.1
A12: Unknown | B12: 1005034.5 | C12: 298752.99
A13: Grand Total | B13: 1.1476327e+08 | C13: 29540010

Sheet Discount Analysis
A3: Discount % | B3: Total Revenue | C3: Total Profit
A4: 0 | B4: 19418494 | C4: 4699612.9
A5: 0.03 | B5: 20083786 | C5: 5377251.1
A6: 0.05 | B6: 31962182 | C6: 8283033.1
A7: 0.08 | B7: 19560063 | C7: 5248118.5
A8: 0.1 | B8: 18841565 | C8: 4736774.5
A9: 0.15 | B9: 4897182.8 | C9: 1195219.5
A10: Grand Total | B10: 1.1476327e+08 | C10: 29540010

Sheet Analysis_Sheet
A1: KPI | B1: Value | D1: Region Performance Summary | K1: Selected Region | L1: East
A2: Total Revenue | B2: =SUM(Cleaned_Sales_Data[Revenue]) -> 1.1476327e+08 | D2: Region | E2: Total Revenue | F2: Total Profit | G2: Order Count | H2: Profit Margin | I2: Performance Status | K2: Total Revenue | L2: =_xlfn.XLOOKUP($L$1,$D$3:$D$7,$E$3:$E$7,"Not Found") -> 22862092
A3: Total Profit | B3: =SUM(Cleaned_Sales_Data[Profit]) -> 29540010 | D3: South | E3: =SUMIFS(Cleaned_Sales_Data[Revenue],Cleaned_Sales_Data[Region],Table1[[#This Row],[Region]]) -> 32131258 | F3: =SUMIFS(Cleaned_Sales_Data[Profit],Cleaned_Sales_Data[Region],Table1[[#This Row],[Region]]) -> 8199036.3 | G3: =COUNTIFS(Cleaned_Sales_Data[Region],D3) -> 331 | H3: =Table1[[#This Row],[Total Profit]]/Table1[[#This Row],[Total Revenue]] -> 0.25517321 | I3: =IF(H3>=25%,"Healthy","Needs Review") -> Healthy | K3: Total Profit | L3: =_xlfn.XLOOKUP(L1,$D$3:$D$7,$F$3:$F$7,"Not Found") -> 5940513.2
A4: Total Orders | B4: =COUNTA(Cleaned_Sales_Data[Order_ID]) -> 1180 | D4: North | E4: =SUMIFS(Cleaned_Sales_Data[Revenue],Cleaned_Sales_Data[Region],Table1[[#This Row],[Region]]) -> 31802415 | F4: =SUMIFS(Cleaned_Sales_Data[Profit],Cleaned_Sales_Data[Region],Table1[[#This Row],[Region]]) -> 8068792 | G4: =COUNTIFS(Cleaned_Sales_Data[Region],D4) -> 325 | H4: =Table1[[#This Row],[Total Profit]]/Table1[[#This Row],[Total Revenue]] -> 0.25371633 | I4: =IF(H4>=25%,"Healthy","Needs Review") -> Healthy | K4: Order Count | L4: =_xlfn.XLOOKUP(L1,$D$3:$D$7,$G$3:$G$7,"Not Found") -> 260
A5: Total Quantity | B5: =SUM(Cleaned_Sales_Data[Quantity]) -> 5218 | D5: East | E5: =SUMIFS(Cleaned_Sales_Data[Revenue],Cleaned_Sales_Data[Region],Table1[[#This Row],[Region]]) -> 22862092 | F5: =SUMIFS(Cleaned_Sales_Data[Profit],Cleaned_Sales_Data[Region],Table1[[#This Row],[Region]]) -> 5940513.2 | G5: =COUNTIFS(Cleaned_Sales_Data[Region],D5) -> 260 | H5: =Table1[[#This Row],[Total Profit]]/Table1[[#This Row],[Total Revenue]] -> 0.25984119 | I5: =IF(H5>=25%,"Healthy","Needs Review") -> Healthy | K5: Profit Margin | L5: =_xlfn.XLOOKUP(L1,$D$3:$D$7,$H$3:$H$7,"Not Found") -> 0.25984119
A6: Average Order Value | B6: =SUM(Cleaned_Sales_Data[Revenue])/COUNTA(Cleaned_Sales_Data[Order_ID]) -> 97257.011 | D6: West | E6: =SUMIFS(Cleaned_Sales_Data[Revenue],Cleaned_Sales_Data[Region],Table1[[#This Row],[Region]]) -> 27308122 | F6: =SUMIFS(Cleaned_Sales_Data[Profit],Cleaned_Sales_Data[Region],Table1[[#This Row],[Region]]) -> 7142724.2 | G6: =COUNTIFS(Cleaned_Sales_Data[Region],D6) -> 256 | H6: =Table1[[#This Row],[Total Profit]]/Table1[[#This Row],[Total Revenue]] -> 0.26156044 | I6: =IF(H6>=25%,"Healthy","Needs Review") -> Healthy
A7: Profit Margin | B7: =SUM(Cleaned_Sales_Data[Profit])/SUM(Cleaned_Sales_Data[Revenue]) -> 0.2573995 | D7: Unknown | E7: =SUMIFS(Cleaned_Sales_Data[Revenue],Cleaned_Sales_Data[Region],Table1[[#This Row],[Region]]) -> 659386.42 | F7: =SUMIFS(Cleaned_Sales_Data[Profit],Cleaned_Sales_Data[Region],Table1[[#This Row],[Region]]) -> 188943.9 | G7: =COUNTIFS(Cleaned_Sales_Data[Region],D7) -> 8 | H7: =Table1[[#This Row],[Total Profit]]/Table1[[#This Row],[Total Revenue]] -> 0.28654503 | I7: =IF(H7>=25%,"Healthy","Needs Review") -> Healthy
K8: Selected Salesperson | L8: Amit
K9: Total Revenue | L9: =INDEX('Salesperson Analysis'!$B:$B,MATCH(L8,'Salesperson Analysis'!$A:$A,0)) -> 14653316
A10: KPI PivotTable | K10: Total Profit | L10: =INDEX('Salesperson Analysis'!$C:$C,MATCH(L8,'Salesperson Analysis'!$A:$A,0)) -> 3668662.8
A11: Total Revenue | B11: 1.1476327e+08
A12: Total Profit | B12: 29540010
A13: Total Orders | B13: 1180
A14: Total Quantity | B14: 5218
A15: Average Order Value
A16: Profit Margin

Sheet Dashboard
A1: Sales Performance & MIS Dashboard
A3: Total Revenue | G3: Total Profit | M3: Total Orders | S3: Total Quantity | Y3: Average Order Value | AE3: Profit Margin
A4: =GETPIVOTDATA("Total Revenue",Analysis_Sheet!$A$10) -> 1.1476327e+08 | G4: =GETPIVOTDATA("Total Profit",Analysis_Sheet!$A$10) -> 29540010 | M4: =GETPIVOTDATA("Total Orders",Analysis_Sheet!$A$10) -> 1180 | S4: =GETPIVOTDATA("Total Quantity",Analysis_Sheet!$A$10) -> 5218 | Y4: =A4/M4 -> 97257.011 | AE4: =G4/A4 -> 0.2573995
